Workbook

Sheet Cover
C11: Independent Financial Snapshot
C12: Position Green - Public Data Review (2023–2024)
C14: Prepared as part of application for FP&A role
C15: Felicia Nata
C18: Table of Contents | M18: Model Checks
C20: Inputs | M20: Balance Sheet Balanced? | Q20: =IF(SUM(Model!G132:M132)>0,1,0) -> 1
C21: Model
C36: This brief snapshot is based solely on publicly available information and is intended for discussion purposes only. The objective is to demonstrate analytical approach and driver-based thinking rather than provide a complete financial assessment.
C39: https://www.linkedin.com/in/yfelnt/

Sheet Inputs
B3: Drivers
H5: Year 1 | I5: Year 2 | J5: Year 3 | K5: Year 4 | L5: Year 5
B7: Driver Switch | E7: 2
B9: License Revenue Growth | H9: {=INDEX(H11:H13,$E$7)} -> 0.55 | I9: {=INDEX(I11:I13,$E$7)} -> 0.45 | J9: {=INDEX(J11:J13,$E$7)} -> 0.35 | K9: {=INDEX(K11:K13,$E$7)} -> 0.28 | L9: {=INDEX(L11:L13,$E$7)} -> 0.22
C11: Base Case | H11: 0.45 | I11: 0.35 | J11: 0.28 | K11: 0.22 | L11: 0.18
C12: Upside | H12: 0.55 | I12: 0.45 | J12: 0.35 | K12: 0.28 | L12: 0.22
C13: Downside | H13: 0.35 | I13: 0.28 | J13: 0.22 | K13: 0.18 | L13: 0.15
B16: Consulting Revenue Growth | H16: {=INDEX(H18:H20,$E$7)} -> 0.4 | I16: {=INDEX(I18:I20,$E$7)} -> 0.3 | J16: {=INDEX(J18:J20,$E$7)} -> 0.25 | K16: {=INDEX(K18:K20,$E$7)} -> 0.2 | L16: {=INDEX(L18:L20,$E$7)} -> 0.15
C18: Base Case | H18: 0.3 | I18: 0.25 | J18: 0.2 | K18: 0.15 | L18: 0.12
C19: Upside | H19: 0.4 | I19: 0.3 | J19: 0.25 | K19: 0.2 | L19: 0.15
C20: Downside | H20: 0.2 | I20: 0.15 | J20: 0.12 | K20: 0.1 | L20: 0.08
B23: Personnel Expenses Growth | H23: {=INDEX(H24:H26,$E$7)} -> 0.82 | I23: {=INDEX(I24:I26,$E$7)} -> 0.72 | J23: {=INDEX(J24:J26,$E$7)} -> 0.62 | K23: {=INDEX(K24:K26,$E$7)} -> 0.55 | L23: {=INDEX(L24:L26,$E$7)} -> 0.5
C24: Base Case | H24: 0.85 | I24: 0.8 | J24: 0.75 | K24: 0.7 | L24: 0.65
C25: Upside | H25: 0.82 | I25: 0.72 | J25: 0.62 | K25: 0.55 | L25: 0.5
C26: Downside | H26: 0.9 | I26: 0.88 | J26: 0.85 | K26: 0.82 | L26: 0.8
B29: Capital Expenditure | H29: {=INDEX(H30:H32,$E$7)} -> 0.08 | I29: {=INDEX(I30:I32,$E$7)} -> 0.07 | J29: {=INDEX(J30:J32,$E$7)} -> 0.06 | K29: {=INDEX(K30:K32,$E$7)} -> 0.05 | L29: {=INDEX(L30:L32,$E$7)} -> 0.04
C30: Base Case | H30: 0.06 | I30: 0.05 | J30: 0.04 | K30: 0.04 | L30: 0.03
C31: Upside | H31: 0.08 | I31: 0.07 | J31: 0.06 | K31: 0.05 | L31: 0.04
C32: Downside | H32: 0.05 | I32: 0.04 | J32: 0.035 | K32: 0.03 | L32: 0.03
B35: Other Inputs
B37: Interest Rates
C38: Long Term Debt | E38: =Model!H109 -> 102930
C39: Finance Expenses | E39: =Model!H57*-1 -> 11323
C40: Interest | E40: =E39/E38 -> 0.1100068
C42: Swedish corporate tax-rate | E42: 0.206
C43: Nordic short-term rates | E43: 0.035
B45: Useful Life Assumptions
C46: Goodwill | E46: 10 years
C47: Development Costs | E47: 10 years

Sheet Model
B3: Assumptions & Drivers
C5: All figures in TNOK thousands unless stated | G5: Year -1 | H5: Year 0 | I5: Year 1 | J5: Year 2 | K5: Year 3 | L5: Year 4 | M5: Year 5
C7: Days in Period (Days) | H7: 365 | I7: 365 | J7: =I7 -> 365 | K7: =J7 -> 365 | L7: =K7 -> 365 | M7: =L7 -> 365
C9: Revenue Drivers
C10: License Revenue Growth (%) | H10: =H176/G176-1 -> 1.0628195 | I10: =Inputs!H9 -> 0.55 | J10: =Inputs!I9 -> 0.45 | K10: =Inputs!J9 -> 0.35 | L10: =Inputs!K9 -> 0.28 | M10: =Inputs!L9 -> 0.22
C11: Consulting Revenue Growth (%) | H11: =H177/G177-1 -> 0.68602741 | I11: =Inputs!H16 -> 0.4 | J11: =Inputs!I16 -> 0.3 | K11: =Inputs!J16 -> 0.25 | L11: =Inputs!K16 -> 0.2 | M11: =Inputs!L16 -> 0.15
C12: Other Revenue (% of Revenue) | G12: =G40/G41 -> 0.0095962052 | H12: =H40/H41 -> 0.0040433037 | I12: =H12 -> 0.0040433037 | J12: =I12 -> 0.0040433037 | K12: =J12 -> 0.0040433037 | L12: =K12 -> 0.0040433037 | M12: =L12 -> 0.0040433037
C14: Cost of Revenue Drivers
C15: Cost of Goods Sold (% of Revenue) | G15: =G44/G41*-1 -> 0.040521561 | H15: =H44/H41*-1 -> 0.028562703 | I15: =H15 -> 0.028562703 | J15: =I15 -> 0.028562703 | K15: =J15 -> 0.028562703 | L15: =K15 -> 0.028562703 | M15: =L15 -> 0.028562703
C16: Personnel Expenses (% of Revenue) | I16: =Inputs!H23 -> 0.82 | J16: =Inputs!I23 -> 0.72 | K16: =Inputs!J23 -> 0.62 | L16: =Inputs!K23 -> 0.55 | M16: =Inputs!L23 -> 0.5
C17: Other Operating Expenses (% of Revenue) | G17: =G49/G41 -> -0.36118018 | H17: =H49/H41 -> -0.24292193 | I17: =H17 -> -0.24292193 | J17: =I17 -> -0.24292193 | K17: =J17 -> -0.24292193 | L17: =K17 -> -0.24292193 | M17: =L17 -> -0.24292193
C18: Operating Expenses | G18: =G48+G49 -> -275412 | H18: =H48+H49 -> -379117 | I18: =I48+I49 -> -505299.95 | J18: =J48+J49 -> -620400.06 | K18: =K48+K49 -> -716889.88 | L18: =L48+L49 -> -812242.25 | M18: =M48+M49 -> -898011
C20: Investments
C21: Capital Expenditure (% of Revenue) | I21: =I41*Inputs!H29 -> 38031.012 | J21: =J41*Inputs!I29 -> 45100.234 | K21: =K41*Inputs!J29 -> 49846.216 | L21: =L41*Inputs!K29 -> 51218.299 | M21: =M41*Inputs!L29 -> 48350.222
C23: Working Capital Drivers
C24: Trade Receivable (Days) | H24: =H92/H178*H7 -> 103.6967 | I24: =H24 -> 103.6967 | J24: =I24 -> 103.6967 | K24: =J24 -> 103.6967 | L24: =K24 -> 103.6967 | M24: =L24 -> 103.6967
C25: Account Payable (% of Operating Expenses) | H25: =H113/H18*-1 -> 0.038317986 | I25: =H25 -> 0.038317986 | J25: =I25 -> 0.038317986 | K25: =J25 -> 0.038317986 | L25: =K25 -> 0.038317986 | M25: =L25 -> 0.038317986
C26: Public Duties Payable | H26: =H114/H188*-1 -> 0.091427408 | I26: =H26 -> 0.091427408 | J26: =I26 -> 0.091427408 | K26: =J26 -> 0.091427408 | L26: =K26 -> 0.091427408 | M26: =L26 -> 0.091427408
C27: Other Current Liabilities | H27: =H115/H190*-1 -> 0.10883975 | I27: =H27 -> 0.10883975 | J27: =I27 -> 0.10883975 | K27: =J27 -> 0.10883975 | L27: =K27 -> 0.10883975 | M27: =L27 -> 0.10883975
C28: Deferred Revenue (% of Revenue) | H28: =H116/H41 -> 0.3038219 | I28: =H28 -> 0.3038219 | J28: =I28 -> 0.3038219 | K28: =J28 -> 0.3038219 | L28: =K28 -> 0.3038219 | M28: =L28 -> 0.3038219
C29: Other Current Receivables | H29: =H93/H41 -> 0.044583225 | I29: =H29 -> 0.044583225 | J29: =I29 -> 0.044583225 | K29: =MEDIAN(I29:J29) -> 0.044583225 | L29: =MEDIAN(J29:K29) -> 0.044583225 | M29: =MEDIAN(K29:L29) -> 0.044583225
C30: Other Non-Current Receivables | H30: =H84/H181 -> 0.042363073 | I30: =H30 -> 0.042363073 | J30: =I30 -> 0.042363073 | K30: =J30 -> 0.042363073 | L30: =K30 -> 0.042363073 | M30: =L30 -> 0.042363073
C31: Prepayment | H31: =H94/H181 -> 0.031524942 | I31: =H31 -> 0.031524942 | J31: =I31 -> 0.031524942 | K31: =J31 -> 0.031524942 | L31: =K31 -> 0.031524942 | M31: =L31 -> 0.031524942
B34: Consolidated Profit and Loss Account
C36: All figures in TNOK thousands unless stated | G36: Year -1 | H36: Year 0 | I36: Year 1 | J36: Year 2 | K36: Year 3 | L36: Year 4 | M36: Year 5
C38: Revenue
C39: Sales Revenue | G39: 181233 | H39: 326131 | I39: =I178 -> 473473.25 | J39: =J178 -> 641694.49 | K39: =K178 -> 827424.74 | L39: =L178 -> 1020240.8 | M39: =M178 -> 1203887.9
C40: Other Revenue | G40: 1756 | H40: 1324 | I40: =I180 -> 1914.3961 | J40: =J180 -> 2594.5657 | K40: =K180 -> 3345.5295 | L40: =L180 -> 4125.1435 | M40: =M180 -> 4867.6842
C41: Total Revenue | G41: =SUM(G39:G40) -> 182989 | H41: =SUM(H39:H40) -> 327455 | I41: =SUM(I39:I40) -> 475387.65 | J41: =SUM(J39:J40) -> 644289.06 | K41: =SUM(K39:K40) -> 830770.27 | L41: =SUM(L39:L40) -> 1024366 | M41: =SUM(M39:M40) -> 1208755.5
C43: Cost of Revenue
C44: Cost of goods sold | G44: -7415 | H44: -9353 | I44: =I15*I181*-1 -> -13578.356 | J44: =J15*J181*-1 -> -18402.637 | K44: =K15*K181*-1 -> -23729.045 | L44: =L15*L181*-1 -> -29258.662 | M44: =M15*M181*-1 -> -34525.326
C45: Gross Profit | G45: =G41+G44 -> 175574 | H45: =H41+H44 -> 318102 | I45: =I41+I44 -> 461809.29 | J45: =J41+J44 -> 625886.42 | K45: =K41+K44 -> 807041.23 | L45: =L41+L44 -> 995107.33 | M45: =M41+M44 -> 1174230.2
C47: Operating Expenses
C48: Personnel expenses | G48: -209320 | H48: -299571 | I48: =I188 -> -389817.87 | J48: =J188 -> -463888.12 | K48: =K188 -> -515077.57 | L48: =L188 -> -563401.29 | M48: =M188 -> -604377.77
C49: Other operating expenses | G49: -66092 | H49: -79546 | I49: =I189 -> -115482.08 | J49: =J189 -> -156511.94 | K49: =K189 -> -201812.32 | L49: =L189 -> -248840.96 | M49: =M189 -> -293633.23
C50: EBITDA | G50: =G45+G48+G49 -> -99838 | H50: =H45+H48+H49 -> -61015 | I50: =I45+I48+I49 -> -43490.664 | J50: =J45+J48+J49 -> 5486.3588 | K50: =K45+K48+K49 -> 90151.342 | L50: =L45+L48+L49 -> 182865.07 | M50: =M45+M48+M49 -> 276219.22
C52: Depreciation and amortization | G52: -49846 | H52: -56724 | I52: =I222*-1 -> -54684.473 | J52: =J222*-1 -> -58281.713 | K52: =K222*-1 -> -61994.155 | L52: =L222*-1 -> -65472.858 | M52: =M222*-1 -> -68317.15
C53: EBIT | G53: =G50+G52 -> -149684 | H53: =H50+H52 -> -117739 | I53: =I50+I52 -> -98175.136 | J53: =J50+J52 -> -52795.355 | K53: =K50+K52 -> 28157.187 | L53: =L50+L52 -> 117392.21 | M53: =M50+M52 -> 207902.07
C55: Financial income and expenses
C56: Finance income | G56: 3085 | H56: 5553 | I56: =I341 -> -1251.4815 | J56: =J341 -> -3833.6665 | K56: =K341 -> -2642.2223 | L56: =L341 -> 3223.0435 | M56: =M341 -> 14167.868
...
