Workbook

Sheet Cover
D15: Turning Data into Decisions
D16: Surgical Science Forecast, Scenarios & Margin Strategy
D26: Prepared as part of application for Financial Controller
D30: Felicia Nata, CTP, FPAP™
D31: Treasury Analyst | Certified Treasury Professional (CTP) | Financial Planning & Analysis Professional (FPAP™)
D37: This model is based solely on publicly available financial data for Surgical Science Sweden AB for the period 2023–2025. Forecasts for 2026–2027 are generated using statistical methods (Forecast.ETS) and scenario-based assumptions. The analysis is for illustrative and demonstration purposes only and does not represent actual company guidance or internal forecasts.

Sheet Outputs
B3: Scenario Analysis Summary
I6: =YEAR(I8) -> 2025 | K6: =YEAR(K8) -> 2026 | O6: =YEAR(O8) -> 2027
I7: 3 | J7: =I7+1 -> 4 | K7: 1 | L7: =K7+1 -> 2 | M7: =L7+1 -> 3 | N7: =M7+1 -> 4 | O7: 1 | P7: =O7+1 -> 2 | Q7: =P7+1 -> 3 | R7: =Q7+1 -> 4
C8: Figures in SEK thousands | I8: 45930 | J8: =EOMONTH(I8,3) -> 46022 | K8: 46112 | L8: =EOMONTH(K8,3) -> 46203 | M8: =EOMONTH(L8,3) -> 46295 | N8: =EOMONTH(M8,3) -> 46387 | O8: =EOMONTH(N8,3) -> 46477 | P8: =EOMONTH(O8,3) -> 46568 | Q8: =EOMONTH(P8,3) -> 46660 | R8: =EOMONTH(Q8,3) -> 46752
C11: Driver Switch | E11: 3
C14: Revenue Growth | I14: =Model!P22 -> 263641 | J14: =Model!Q22 -> 268854 | K14: =Model!R22 -> 286305.13 | L14: =Model!S22 -> 307768.71 | M14: =Model!T22 -> 333970.98 | N14: =Model!U22 -> 365836.98 | O14: =Model!V22 -> 404463.58 | P14: =Model!W22 -> 451236.72 | ... R14: =Model!Y22 -> 577142.2
D15: Worst Case | H15: 1 | I15: 263641 | J15: 268854 | K15: 280928.05 | L15: 296369.96 | M15: 315674.39 | N15: 339481.12 | O15: 368535.34 | P15: 403782.94 | Q15: 446507.66 | R15: 498342.89
D16: Base Case | H16: 2 | I16: 263641 | J16: 268854 | K16: 283616.59 | L16: 302042.45 | M16: 324736.78 | N16: 352474.33 | O16: 386165.31 | P16: 426960.73 | Q16: 476407.52 | R16: 536477.91
D17: Best Case | H17: 3 | I17: 263641 | J17: 268854 | K17: 286305.13 | L17: 307768.71 | M17: 333970.98 | N17: 365836.98 | O17: 404463.58 | P17: 451236.72 | Q17: 508007.3 | R17: 577142.2
C20: Earning Before Interest and Tax | I20: =Model!P31 -> 27249 | J20: =Model!Q31 -> 40142 | K20: =Model!R31 -> 27998.891 | L20: =Model!S31 -> 30540.596 | M20: =Model!T31 -> 46371.362 | N20: =Model!U31 -> 47071.879 | O20: =Model!V31 -> 29906.295 | P20: =Model!W31 -> 34013.794 | ... R20: =Model!Y31 -> 60493.595
D21: Worst Case | H21: 1 | I21: 27249 | J21: 40142 | K21: 16235.923 | L21: 17554.673 | M21: 31203.932 | N21: 30101.452 | O21: 12508.324 | P21: 14285.456 | Q21: 33485.944 | R21: 32300.47
D22: Base Case | H22: 2 | I22: 27249 | J22: 40142 | K22: 22063.636 | L22: 23931.517 | M22: 38594.472 | N22: 38303.034 | O22: 20830.002 | P22: 23644.679 | Q22: 45256.442 | R22: 45501.779
D23: Best Case | H23: 3 | I23: 27249 | J23: 40142 | K23: 27998.891 | L23: 30540.596 | M23: 46371.362 | N23: 47071.879 | O23: 29906.295 | P23: 34013.794 | Q23: 58418.417 | R23: 60493.595
C26: EBIT Margin | I26: =Model!P31/Model!P22 -> 0.10335646 | J26: =Model!Q31/Model!Q22 -> 0.1493078 | K26: =Model!R31/Model!R22 -> 0.097793884 | L26: =Model!S31/Model!S22 -> 0.099232295 | M26: =Model!T31/Model!T22 -> 0.13884848 | N26: =Model!U31/Model!U22 -> 0.128669 | O26: =Model!V31/Model!V22 -> 0.073940637 | P26: =Model!W31/Model!W22 -> 0.075379048 | ... R26: =Model!Y31/Model!Y22 -> 0.10481575
D27: Worst Case | H27: 1 | I27: 0.10335646 | J27: 0.1493078 | K27: 0.057793884 | L27: 0.059232295 | M27: 0.098848477 | N27: 0.088669002 | O27: 0.033940637 | P27: 0.035379048 | Q27: 0.07499523 | R27: 0.064815755
D28: Base Case | H28: 2 | I28: 0.10335646 | J28: 0.1493078 | K28: 0.077793884 | L28: 0.079232295 | M28: 0.11884848 | N28: 0.108669 | O28: 0.053940637 | P28: 0.055379048 | Q28: 0.09499523 | R28: 0.084815755
D29: Best Case | H29: 3 | I29: 0.10335646 | J29: 0.1493078 | K29: 0.097793884 | L29: 0.099232295 | M29: 0.13884848 | N29: 0.128669 | O29: 0.073940637 | P29: 0.075379048 | Q29: 0.11499523 | R29: 0.10481575
R31: These forecasts require the workbook calculation to be set to automatic to update.
B35: Scenario Analysis
C38: Figures in SEK thousands | K38: These graphs require the workbook calculation to be set to automatic to update.
C40: Revenue | K40: Scenarios: Best, Base, Worst
B66: Sensitivity Analysis 2026
B69: {=CONCATENATE("Model Running: ",INDEX(D15:D17,E11)," Scenario ")} -> Model Running: Best Case Scenario | I69: Operating Profit Margin
B71: Revenue | E71: =SUM(Model!R22:U22) -> 1293881.8 | I71: Research and Development
B72: Cost of Goods Sold | E72: =SUM(Model!R23:U23)/E71 -> -0.3228492 | G72: Gross Profit | H72: =E81 -> 0.11746261 | I72: =J72+0.01 -> -0.20691814 | J72: =K72+0.01 -> -0.21691814 | K72: =E78 -> -0.22691814 | L72: =K72-0.01 -> -0.23691814 | M72: =L72-0.01 -> -0.24691814
H73: =H74-0.01 -> 0.6571508 | I73: 0.11746261 | J73: 0.12746261 | K73: 0.12746261 | L73: 0.11746261 | M73: 0.097462606
B74: Gross Profit | E74: =SUM(Model!R24:U24)/E71 -> 0.6771508 | H74: =H75-0.01 -> 0.6671508 | I74: 0.10746261 | J74: 0.11746261 | K74: 0.11746261 | L74: 0.10746261 | M74: 0.087462606
H75: =E74 -> 0.6771508 | I75: 0.10746261 | J75: 0.11746261 | K75: 0.11746261 | L75: 0.10746261 | M75: 0.087462606
B76: Sales costs | E76: =SUM(Model!R26:U26)/E71 -> -0.22071916 | H76: =H75+0.01 -> 0.6871508 | I76: 0.11746261 | J76: 0.12746261 | K76: 0.12746261 | L76: 0.11746261 | M76: 0.097462606
B77: Administration costs | E77: =SUM(Model!R27:U27)/E71 -> -0.094906574 | H77: =H76+0.01 -> 0.6971508 | I77: 0.13746261 | J77: 0.14746261 | K77: 0.14746261 | L77: 0.13746261 | M77: 0.11746261
B78: Research and development costs | E78: =SUM(Model!R28:U28)/E71 -> -0.22691814
B79: Other operating income and costs | E79: =SUM(Model!R29:U29)/E71 -> -0.017144315
I80: Operating Profit Margin
B81: Operating profit | E81: =SUM(E74:E79) -> 0.11746261
I82: Sales Cost
G83: Gross Profit | H83: =E81 -> 0.11746261 | I83: =J83+0.01 -> -0.20071916 | J83: =K83+0.01 -> -0.21071916 | K83: =E76 -> -0.22071916 | L83: =K83-0.01 -> -0.23071916 | M83: =L83-0.01 -> -0.24071916
H84: =H85-0.01 -> 0.6571508 | I84: 0.11746261 | J84: 0.12746261 | K84: 0.12746261 | L84: 0.11746261 | M84: 0.097462606
H85: =H86-0.01 -> 0.6671508 | I85: 0.10746261 | J85: 0.11746261 | K85: 0.11746261 | L85: 0.10746261 | M85: 0.087462606
H86: =E74 -> 0.6771508 | I86: 0.10746261 | J86: 0.11746261 | K86: 0.11746261 | L86: 0.10746261 | M86: 0.087462606
H87: =H86+0.01 -> 0.6871508 | I87: 0.11746261 | J87: 0.12746261 | K87: 0.12746261 | L87: 0.11746261 | M87: 0.097462606
...

Sheet Model
B3: Forecast Key Assumptions
C6: Cost of goods sold | F6: =AVERAGE(F23:Q23)/AVERAGE(F22:Q22) -> -0.3228492
C7: Administration costs | F7: =AVERAGE(F27:Q27)/AVERAGE(F22:Q22) -> -0.094906574
C8: Net Other Operating | F8: =AVERAGE(F29:Q29)/AVERAGE(F22:Q22) -> -0.017144315
C9: Net Financial | F9: 0.02
C10: =C36 -> Taxes | F10: =AVERAGE(F36:Q36)/AVERAGE(F34:Q34) -> -0.17864659
B14: Consolidated Income Statement
F17: =YEAR(F19) -> 2023 | J17: =YEAR(J19) -> 2024 | N17: =YEAR(N19) -> 2025 | R17: =YEAR(R19) -> 2026 | V17: =YEAR(V19) -> 2027
F18: 1 | G18: =F18+1 -> 2 | H18: =G18+1 -> 3 | I18: =H18+1 -> 4 | J18: 1 | K18: =J18+1 -> 2 | L18: =K18+1 -> 3 | M18: =L18+1 -> 4 | N18: 1 | O18: =N18+1 -> 2 | P18: =O18+1 -> 3 | Q18: =P18+1 -> 4 | R18: 1 | S18: =R18+1 -> 2 | T18: =S18+1 -> 3 | U18: =T18+1 -> 4 | V18: 2 | W18: =V18+1 -> 3 | X18: =W18+1 -> 4 | Y18: =X18+1 -> 5
C19: Figures in SEK thousands | F19: 45016 | G19: =EOMONTH(F19,3) -> 45107 | H19: =EOMONTH(G19,3) -> 45199 | I19: =EOMONTH(H19,3) -> 45291 | J19: 45382 | K19: =EOMONTH(J19,3) -> 45473 | L19: =EOMONTH(K19,3) -> 45565 | M19: =EOMONTH(L19,3) -> 45657 | N19: =EOMONTH(M19,3) -> 45747 | O19: =EOMONTH(N19,3) -> 45838 | P19: =EOMONTH(O19,3) -> 45930 | Q19: =EOMONTH(P19,3) -> 46022 | R19: =EOMONTH(Q19,3) -> 46112 | ... Y19: =EOMONTH(X19,3) -> 46752
C22: Net sales | F22: 229077 | G22: 216237 | H22: 210246 | I22: 227293 | J22: 188243 | K22: 212466 | L22: 231828 | M22: 251549 | N22: 250691 | O22: 209157 | P22: 263641 | Q22: 268854 | R22: =Q22*(1+R54) -> 286305.13 | S22: =R22*(1+S54) -> 307768.71 | T22: =S22*(1+T54) -> 333970.98 | U22: =T22*(1+U54) -> 365836.98 | V22: =U22*(1+V54) -> 404463.58 | W22: =V22*(1+W54) -> 451236.72 | X22: =W22*(1+X54) -> 508007.3 | Y22: =X22*(1+Y54) -> 577142.2
C23: Cost of goods sold | F23: -70392 | G23: -69498 | H23: -65221 | I23: -64864 | J23: -64918 | K23: -68982 | L23: -70816 | M23: -81474 | N23: -78092 | O23: -72763 | P23: -93211 | Q23: -90601 | R23: =R22*$F$6 -> -92433.384 | S23: =S22*$F$6 -> -99362.884 | T23: =T22*$F$6 -> -107822.27 | U23: =U22*$F$6 -> -118110.18 | V23: =V22*$F$6 -> -130580.75 | W23: =W22*$F$6 -> -145681.41 | X23: =X22*$F$6 -> -164009.75 | Y23: =Y22*$F$6 -> -186329.9
C24: Gross profit | F24: 158685 | G24: 146740 | H24: 145025 | I24: 162429 | J24: =SUM(J22:J23) -> 123325 | K24: =SUM(K22:K23) -> 143484 | L24: =SUM(L22:L23) -> 161012 | M24: =SUM(M22:M23) -> 170075 | N24: =SUM(N22:N23) -> 172599 | O24: =SUM(O22:O23) -> 136394 | P24: =SUM(P22:P23) -> 170430 | Q24: =SUM(Q22:Q23) -> 178253 | R24: =R22+R23 -> 193871.75 | S24: =S22+S23 -> 208405.83 | T24: =T22+T23 -> 226148.71 | U24: =U22+U23 -> 247726.8 | V24: =V22+V23 -> 273882.84 | W24: =W22+W23 -> 305555.3 | X24: =X22+X23 -> 343997.55 | Y24: =Y22+Y23 -> 390812.3
C26: Sales costs | F26: -46949 | G26: -41022 | H26: -37042 | I26: -42502 | J26: -40456 | K26: -42290 | L26: -42617 | M26: -49898 | N26: -53122 | O26: -57783 | P26: -56466 | Q26: -46981 | R26: =R66*R22 -> -66341.852 | S26: =S66*S22 -> -68880.685 | T26: =T66*T22 -> -70244.531 | U26: =U66*U22 -> -80117.432 | V26: =V66*V22 -> -99377.122 | W26: =W66*W22 -> -107299.75 | X26: =X66*X22 -> -113953.65 | Y26: =Y66*Y22 -> -134463.38
C27: Administration costs | F27: -16665 | G27: -15444 | H27: -20649 | I27: -19750 | J27: -15744 | K27: -20998 | L27: -18040 | M27: -22338 | N27: -43752 | O27: -23493 | P27: -20484 | Q27: -24517 | R27: =$F$7*R22 -> -27172.239 | S27: =$F$7*S22 -> -29209.274 | T27: =$F$7*T22 -> -31696.041 | U27: =$F$7*U22 -> -34720.334 | V27: =$F$7*V22 -> -38386.253 | W27: =$F$7*W22 -> -42825.33 | X27: =$F$7*X22 -> -48213.233 | Y27: =$F$7*Y22 -> -54774.588
C28: Research and development costs | F28: -46059 | G28: -48452 | H28: -40810 | I28: -46247 | J28: -45039 | K28: -48841 | L28: -50575 | M28: -51656 | N28: -55206 | O28: -52123 | P28: -55027 | Q28: -59753 | R28: =R60*R22 -> -67450.259 | S28: =S60*S22 -> -74498.79 | T28: =T60*T22 -> -72111.077 | U28: =U60*U22 -> -79545.132 | V28: =V60*V22 -> -99278.916 | W28: =W60*W22 -> -113680.28 | X28: =X60*X22 -> -114702.82 | Y28: =Y60*Y22 -> -131186.03
C29: Other operating income and costs | F29: 4255 | G29: 5716 | H29: 4169 | I29: -16275 | J29: 3890 | K29: 2075 | L29: -3995 | M29: -7056 | N29: 3419 | O29: -25440 | P29: -11204 | Q29: -6860 | R29: =$F$8*R22 -> -4908.5054 | S29: =$F$8*S22 -> -5276.4838 | T29: =$F$8*T22 -> -5725.7037 | U29: =$F$8*U22 -> -6272.0244 | V29: =$F$8*V22 -> -6934.2511 | W29: =$F$8*W22 -> -7736.1444 | X29: =$F$8*X22 -> -8709.4373 | Y29: =$F$8*Y22 -> -9894.7077
C31: Operating profit | F31: 53267 | G31: 47538 | H31: 50693 | I31: 37655 | J31: =SUM(J24:J29) -> 25976 | K31: =SUM(K24:K29) -> 33430 | L31: =SUM(L24:L29) -> 45785 | M31: =SUM(M24:M29) -> 39127 | N31: =SUM(N24:N29) -> 23938 | O31: =SUM(O24:O29) -> -22445 | P31: =SUM(P24:P29) -> 27249 | Q31: =SUM(Q24:Q29) -> 40142 | ... Y31: =SUM(Y24:Y29) -> 60493.595
C33: Financial income and costs | F33: 1761 | G33: -5176 | H33: 1741 | I33: 80784 | J33: 1862 | K33: 4376 | L33: 7239 | M33: 295 | N33: 22273 | O33: 3728 | P33: 2900 | Q33: 2353 | R33: =$F$9*R22 -> 5726.1026 | S33: =$F$9*S22 -> 6155.3742 | T33: =$F$9*T22 -> 6679.4196 | U33: =$F$9*U22 -> 7316.7396 | V33: =$F$9*V22 -> 8089.2716 | W33: =$F$9*W22 -> 9024.7343 | X33: =$F$9*X22 -> 10160.146 | Y33: =$F$9*Y22 -> 11542.844
C34: Profit after financial items | F34: 55029 | G34: 42362 | H34: 52434 | I34: 118439 | J34: =J31+J33 -> 27838 | K34: =K31+K33 -> 37806 | L34: =L31+L33 -> 53024 | M34: =M31+M33 -> 39422 | N34: =N31+N33 -> 46211 | O34: =O31+O33 -> -18717 | P34: =P31+P33 -> 30149 | Q34: =Q31+Q33 -> 42495 | ... Y34: =Y31+Y33 -> 72036.439
C36: Taxes | F36: -5210 | G36: -3573 | H36: -5031 | I36: -20478 | J36: -4046 | K36: -9238 | L36: -10002 | M36: -3159 | N36: -12974 | O36: -1359 | P36: -9746 | Q36: -9240 | R36: =$F$10*R34 -> -6024.855 | S36: =$F$10*S34 -> -6555.6099 | T36: =$F$10*T34 -> -9477.3412 | U36: =$F$10*U34 -> -9716.3412 | V36: =$F$10*V34 -> -6787.7783 | W36: =$F$10*W34 -> -7688.6862 | X36: =$F$10*X34 -> -12251.326 | Y36: =$F$10*Y34 -> -12869.064
C38: Net profit | F38: 49819 | G38: 38789 | H38: 47403 | I38: 97962 | J38: =J34+J36 -> 23792 | K38: =K34+K36 -> 28568 | L38: =L34+L36 -> 43022 | M38: =M34+M36 -> 36263 | N38: =N34+N36 -> 33237 | O38: =O34+O36 -> -20076 | P38: =P34+P36 -> 20403 | Q38: =Q34+Q36 -> 33255 | ... Y38: =Y34+Y36 -> 59167.375
B42: Scenario Schedule
F45: =YEAR(F47) -> 2023 | J45: =YEAR(J47) -> 2024 | N45: =YEAR(N47) -> 2025 | R45: =YEAR(R47) -> 2026 | V45: =YEAR(V47) -> 2027
F46: 1 | G46: =F46+1 -> 2 | H46: =G46+1 -> 3 | I46: =H46+1 -> 4 | J46: 1 | K46: =J46+1 -> 2 | L46: =K46+1 -> 3 | M46: =L46+1 -> 4 | N46: 1 | O46: =N46+1 -> 2 | P46: =O46+1 -> 3 | Q46: =P46+1 -> 4 | R46: 1 | S46: =R46+1 -> 2 | T46: =S46+1 -> 3 | U46: =T46+1 -> 4 | V46: 2 | W46: =V46+1 -> 3 | X46: =W46+1 -> 4 | Y46: =X46+1 -> 5
C47: Figures in SEK thousands | F47: 45016 | G47: =EOMONTH(F47,3) -> 45107 | H47: =EOMONTH(G47,3) -> 45199 | I47: =EOMONTH(H47,3) -> 45291 | J47: 45382 | K47: =EOMONTH(J47,3) -> 45473 | L47: =EOMONTH(K47,3) -> 45565 | M47: =EOMONTH(L47,3) -> 45657 | N47: =EOMONTH(M47,3) -> 45747 | O47: =EOMONTH(N47,3) -> 45838 | P47: =EOMONTH(O47,3) -> 45930 | Q47: =EOMONTH(P47,3) -> 46022 | R47: =EOMONTH(Q47,3) -> 46112 | ... Y47: =EOMONTH(X47,3) -> 46752
C51: Driver Switch | D51: =Outputs!E11 -> 3
C54: Revenue Growth | G54: =G22/F22-1 -> -0.056051022 | H54: =H22/G22-1 -> -0.027705712 | I54: =I22/H22-1 -> 0.08108121 | J54: =J22/I22-1 -> -0.17180468 | K54: =K22/J22-1 -> 0.12867942 | L54: =L22/K22-1 -> 0.091129875 | M54: =M22/L22-1 -> 0.085067378 | N54: =N22/M22-1 -> -0.0034108663 | ... Q54: =Q22/P22-1 -> 0.019773101 | R54: {=INDEX(R56:R58,$D$51)} -> 0.064909319 | S54: {=INDEX(S56:S58,$D$51)} -> 0.074967508 | T54: {=INDEX(T56:T58,$D$51)} -> 0.085136227 | U54: {=INDEX(U56:U58,$D$51)} -> 0.095415476 | V54: {=INDEX(V56:V58,$D$51)} -> 0.10558419 | W54: {=INDEX(W56:W58,$D$51)} -> 0.11564238 | X54: {=INDEX(X56:X58,$D$51)} -> 0.1258111 | Y54: {=INDEX(Y56:Y58,$D$51)} -> 0.13609035
D56: Worst Case | R56: =R57-0.01 -> 0.044909319 | S56: =S57-0.01 -> 0.054967508 | T56: =T57-0.01 -> 0.065136227 | U56: =U57-0.01 -> 0.075415476 | V56: =V57-0.01 -> 0.085584195 | W56: =W57-0.01 -> 0.095642384 | X56: =X57-0.01 -> 0.1058111 | Y56: =Y57-0.01 -> 0.11609035
D57: Base Case | R57: =_xlfn.FORECAST.ETS(R47,$G$54:$Q$54,$G$47:$Q$47) -> 0.054909319 | S57: =_xlfn.FORECAST.ETS(S47,$G$54:$Q$54,$G$47:$Q$47) -> 0.064967508 | T57: =_xlfn.FORECAST.ETS(T47,$G$54:$Q$54,$G$47:$Q$47) -> 0.075136227 | U57: =_xlfn.FORECAST.ETS(U47,$G$54:$Q$54,$G$47:$Q$47) -> 0.085415476 | V57: =_xlfn.FORECAST.ETS(V47,$G$54:$Q$54,$G$47:$Q$47) -> 0.095584195 | W57: =_xlfn.FORECAST.ETS(W47,$G$54:$Q$54,$G$47:$Q$47) -> 0.10564238 | X57: =_xlfn.FORECAST.ETS(X47,$G$54:$Q$54,$G$47:$Q$47) -> 0.1158111 | Y57: =_xlfn.FORECAST.ETS(Y47,$G$54:$Q$54,$G$47:$Q$47) -> 0.12609035
D58: Best Case | R58: =R57+0.01 -> 0.064909319 | S58: =S57+0.01 -> 0.074967508 | T58: =T57+0.01 -> 0.085136227 | U58: =U57+0.01 -> 0.095415476 | V58: =V57+0.01 -> 0.10558419 | W58: =W57+0.01 -> 0.11564238 | X58: =X57+0.01 -> 0.1258111 | Y58: =Y57+0.01 -> 0.13609035
C60: R&D Costs (% of Revenue) | F60: =F28/F22 -> -0.2010634 | G60: =G28/G22 -> -0.22406896 | H60: =H28/H22 -> -0.19410595 | I60: =I28/I22 -> -0.20346865 | J60: =J28/J22 -> -0.23925989 | K60: =K28/K22 -> -0.22987678 | L60: =L28/L22 -> -0.21815743 | M60: =M28/M22 -> -0.20535164 | ... Q60: =Q28/Q22 -> -0.22225074 | R60: {=INDEX(R62:R64,$D$51)} -> -0.23558872 | S60: {=INDEX(S62:S64,$D$51)} -> -0.24206096 | T60: {=INDEX(T62:T64,$D$51)} -> -0.21592019 | U60: {=INDEX(U62:U64,$D$51)} -> -0.21743327 | V60: {=INDEX(V62:V64,$D$51)} -> -0.24545823 | W60: {=INDEX(W62:W64,$D$51)} -> -0.25193047 | X60: {=INDEX(X62:X64,$D$51)} -> -0.2257897 | Y60: {=INDEX(Y62:Y64,$D$51)} -> -0.22730278
D62: Worst Case | R62: =R63-0.01 -> -0.25558872 | S62: =S63-0.01 -> -0.26206096 | T62: =T63-0.01 -> -0.23592019 | U62: =U63-0.01 -> -0.23743327 | V62: =V63-0.01 -> -0.26545823 | W62: =W63-0.01 -> -0.27193047 | X62: =X63-0.01 -> -0.2457897 | Y62: =Y63-0.01 -> -0.24730278
D63: Base Case | R63: =_xlfn.FORECAST.ETS(R47,$F$60:$Q$60,$F$47:$Q$47) -> -0.24558872 | S63: =_xlfn.FORECAST.ETS(S47,$F$60:$Q$60,$F$47:$Q$47) -> -0.25206096 | T63: =_xlfn.FORECAST.ETS(T47,$F$60:$Q$60,$F$47:$Q$47) -> -0.22592019 | U63: =_xlfn.FORECAST.ETS(U47,$F$60:$Q$60,$F$47:$Q$47) -> -0.22743327 | V63: =_xlfn.FORECAST.ETS(V47,$F$60:$Q$60,$F$47:$Q$47) -> -0.25545823 | W63: =_xlfn.FORECAST.ETS(W47,$F$60:$Q$60,$F$47:$Q$47) -> -0.26193047 | X63: =_xlfn.FORECAST.ETS(X47,$F$60:$Q$60,$F$47:$Q$47) -> -0.2357897 | Y63: =_xlfn.FORECAST.ETS(Y47,$F$60:$Q$60,$F$47:$Q$47) -> -0.23730278
D64: Best Case | R64: =R63+0.01 -> -0.23558872 | S64: =S63+0.01 -> -0.24206096 | T64: =T63+0.01 -> -0.21592019 | U64: =U63+0.01 -> -0.21743327 | V64: =V63+0.01 -> -0.24545823 | W64: =W63+0.01 -> -0.25193047 | X64: =X63+0.01 -> -0.2257897 | Y64: =Y63+0.01 -> -0.22730278
C66: Sales Costs (% of Revenue) | F66: =F26/F22 -> -0.20494855 | G66: =G26/G22 -> -0.18970851 | H66: =H26/H22 -> -0.17618409 | I66: =I26/I22 -> -0.18699212 | J66: =J26/J22 -> -0.2149137 | K66: =K26/K22 -> -0.19904361 | L66: =L26/L22 -> -0.18383025 | M66: =M26/M22 -> -0.19836294 | ... Q66: =Q26/Q22 -> -0.1747454 | R66: {=INDEX(R68:R70,$D$51)} -> -0.2317173 | S66: {=INDEX(S68:S70,$D$51)} -> -0.22380665 | T66: {=INDEX(T68:T70,$D$51)} -> -0.21033124 | U66: {=INDEX(U68:U70,$D$51)} -> -0.21899763 | V66: {=INDEX(V68:V70,$D$51)} -> -0.24570104 | W66: {=INDEX(W68:W70,$D$51)} -> -0.23779039 | X66: {=INDEX(X68:X70,$D$51)} -> -0.22431498 | Y66: {=INDEX(Y68:Y70,$D$51)} -> -0.23298137
D68: Worst Case | R68: =R69-0.01 -> -0.2517173 | S68: =S69-0.01 -> -0.24380665 | T68: =T69-0.01 -> -0.23033124 | U68: =U69-0.01 -> -0.23899763 | V68: =V69-0.01 -> -0.26570104 | W68: =W69-0.01 -> -0.25779039 | X68: =X69-0.01 -> -0.24431498 | Y68: =Y69-0.01 -> -0.25298137
D69: Base Case | R69: =_xlfn.FORECAST.ETS(R47,$F$66:$Q$66,$F$47:$Q$47) -> -0.2417173 | S69: =_xlfn.FORECAST.ETS(S47,$F$66:$Q$66,$F$47:$Q$47) -> -0.23380665 | T69: =_xlfn.FORECAST.ETS(T47,$F$66:$Q$66,$F$47:$Q$47) -> -0.22033124 | U69: =_xlfn.FORECAST.ETS(U47,$F$66:$Q$66,$F$47:$Q$47) -> -0.22899763 | V69: =_xlfn.FORECAST.ETS(V47,$F$66:$Q$66,$F$47:$Q$47) -> -0.25570104 | W69: =_xlfn.FORECAST.ETS(W47,$F$66:$Q$66,$F$47:$Q$47) -> -0.24779039 | X69: =_xlfn.FORECAST.ETS(X47,$F$66:$Q$66,$F$47:$Q$47) -> -0.23431498 | Y69: =_xlfn.FORECAST.ETS(Y47,$F$66:$Q$66,$F$47:$Q$47) -> -0.24298137
D70: Best Case | R70: =R69+0.01 -> -0.2317173 | S70: =S69+0.01 -> -0.22380665 | T70: =T69+0.01 -> -0.21033124 | U70: =U69+0.01 -> -0.21899763 | V70: =V69+0.01 -> -0.24570104 | W70: =W69+0.01 -> -0.23779039 | X70: =X69+0.01 -> -0.22431498 | Y70: =Y69+0.01 -> -0.23298137
H102: Coefficients | L102: Research and Development Costs | M102: Sales Costs | N102: Net Sales
...
