Workbook

Sheet Cover
C14: Treasury Intelligence Brief (2020–2024) | N14: Table of Contents
C15: Sinch Group
C16: Liquidity | FX Risk | Global Cash Strategy | O16: Inputs
O17: Dashboard
O18: Liquidity Forecast Simulation
C27: Prepared as part of application for Treasury Manager role
C29: Felicia Nata, CTP
C30: M. Sc. In Finance - Umeå University
C31: Cerified Treasury Professional (CTP)
C37: This brief is based solely on publicly available information and is intended to demonstrate analytical thinking and treasury perspective.
C38: https://www.linkedin.com/in/yfelnt/

Sheet Inputs
H1: Treasury Intelligence Brief (2020–2024)
B3: Sinch Treasury Dataset (SEKm)
D5: 2020 | E5: 2021 | F5: 2022 | G5: 2023 | H5: 2024
B7: Revenue | D7: 8023 | E7: 16177 | F7: 27722 | G7: 28745 | H7: 28712
B8: Gross Profit | D8: 2183 | E8: 3933 | F8: 8810 | G8: 9542 | H8: 9685
B9: EBITDA | D9: 715 | E9: 831 | F9: 2774 | G9: 3074 | H9: 2665
B10: Adjusted EBITDA | D10: 989 | E10: 1322 | F10: 3124 | G10: 3637 | H10: 3586
B11: Net Income | D11: 446 | E11: 908 | F11: -4943 | G11: 42 | H11: -6413
B12: Operating Cash Flow | D12: 454 | E12: 329 | F12: 2508 | G12: 1788 | H12: 2944
B13: Investing Cash Flow | D13: -2973 | E13: -29059 | F13: -691 | G13: -649 | H13: -604
B14: Financing Cash Flow | D14: 5231 | E14: 26454 | F14: -1508 | G14: -2342 | H14: -2234
B15: Net Cash Flow | D15: 2713 | E15: -2276 | F15: 309 | G15: -1203 | H15: 105
B16: Cash & Cash Equivalents | D16: 3123 | E16: 1871 | F16: 2173 | G16: 1012 | H16: 1083
B17: Total Assets | D17: 11634 | E17: 57081 | F17: 57284 | G17: 53134 | H17: 48004
B18: Equity | D18: 7513 | E18: 34053 | F18: 34432 | G18: 33663 | H18: 29025
... B24: EBITDA Margin (%) | D24: 8.9 | E24: 5.1 | F24: 10 | G24: 10.7 | H24: 9.3
B27: Additional Metrics
D29: 2020 | E29: 2021 | F29: 2022 | G29: 2023 | H29: 2024
B31: Net Debt Change (%) | E31: =E21-D21 -> 12629 | F31: =F21-E21 -> -1478 | G31: =G21-F21 -> -1175 | H31: =H21-G21 -> -1975
B32: Cash / Current Liabilities | D32: =D16/D19 -> 1.2319527 | E32: =E16/E19 -> 0.1191037 | F32: =F16/F19 -> 0.35448613 | G32: =G16/G19 -> 0.12643678 | H32: =H16/H19 -> 0.1074938
B33: Operating Cash Flow / EBITDA | D33: =D12/D9 -> 0.63496503 | E33: =E12/E9 -> 0.39590854 | F33: =F12/F9 -> 0.90410959 | G33: =G12/G9 -> 0.58165257 | H33: =H12/H9 -> 1.1046904
B36: Regional Revenue Share
C37: Region | D37: Revenue (SEKm) | E37: %
C38: Americas | D38: 18109 | E38: =D38/D41 -> 0.6307119
C39: EMEA | D39: 6640 | E39: =D39/D41 -> 0.23126219
C40: APAC | D40: 3963 | E40: =D40/D41 -> 0.13802591
C41: Total | D41: 28712
B43: FX Exposure Table
C44: Region | D44: Revenue Share | E44: Primary Currency Exposure
C45: Americas | D45: 0.63 | E45: USD
C46: EMEA | D46: 0.23 | E46: EUR / SEK / GBP
C47: APAC | D47: 0.14 | E47: AUD / INR / SGD

Sheet Dashboard
P1: Treasury Intelligence Brief (2020–2024)
B3: Understanding the Business
B5: How Sinch Generates Cash
B6: Sinch operates a global communications platform that enables businesses to connect with customers through messaging, voice, and email APIs.
B7: With more than 175,000 businesses worldwide, Sinch processes a significant volume of transactions across multiple currencies and jurisdictions.
B9: This creates several treasury priorities:
B10: • Managing liquidity across global subsidiaries
B11: • Monitoring FX exposure from international revenue streams
B12: • Supporting large transaction flows through banking infrastructure
B13: • Ensuring efficient funding and capital allocation
B15: Treasury therefore plays a central role in ensuring financial stability and operational scalability.
B18: Liquidity Position
B20: Global Liquidity Snapshot
B21: Overview of Sinch's liquidity position based on publicly available financial data (FY2024).
B23: Cash Balance | F23: Total Debt | J23: Net Debt | N23: Available Cash
B24: =Inputs!H16 -> 1083 | F24: =Inputs!H21+Inputs!H16 -> 7095 | J24: =Inputs!H21 -> 6012 | N24: =Inputs!H16 -> 1083
B27: Available cash at year-end | F27: Approx. derived from Net Debt + Cash | J27: Reported company metric | N27: Cash available for operations
J41: Insights
J42: • Cash balances declined as the company prioritized deleveraging and balance sheet strengthening.
B43: Short-Term Liquidity Coverage | E43: =Inputs!H32 -> 0.1074938 | J43: • Net debt has fallen significantly since 2021, improving financial flexibility.
J44: • Strong operating cash flow supports ongoing liquidity needs.
B46: Sinch reduced net leverage from 2.9× EBITDA in 2021 to 1.5× in 2024, reflecting a clear focus on balance sheet strengthening and financial flexibility.
B49: FX Exposure & Currency Risk
B51: FX Exposure & Currency Risk
B52: Overview of foreign exchange exposure based on geographic revenue distribution and publicly available financial information.
I54: Source of FX Risk | L54: Example
I55: Customer billing | L55: Messaging services billed globally
I56: Vendor payments | L56: Telecom infrastructure providers
I57: Intercompany transfers | L57: Funding between subsidiaries
I58: Revenue translation | L58: Foreign revenue translated into SEK
I60: Country | J60: Revenue | K60: Currency | M60: Treasury FX Management
I61: USA | J61: 16420 | K61: USD | M61: • FX forward contracts • Natural hedging across regions • Internal netting programs • FX hedging strategies to reduce earnings volatility • Currency exposure monitoring
I62: UK | J62: 2051 | K62: GBP
I63: India | J63: 1695 | K63: INR
I64: Australia | J64: 1150 | K64: AUD
B65: Geographic revenue distribution used as proxy for currency exposure. | I65: France | J65: 933 | K65: EUR
B67: • The majority of revenue originates from the Americas (63%), creating significant USD exposure. • EMEA and APAC operations introduce additional exposure across EUR, GBP, AUD, and emerging market currencies. • Active FX risk management is important to reduce earnings volatility from currency fluctuations.
B69: With a majority of revenue generated outside Sweden, currency volatility represents an important financial risk factor for the group.
B72: Treasury Optimization Opportunities
B74: Treasury Optimization Opportunities
...

Sheet Liquidity Forecast Simulation
W1: Treasury Intelligence Brief (2020–2024)
B3: Liquidity Forecast Simulation (12-Month)
B5: Liquidity Forecast Scenario | L5: 12-Month Liquidity Outlook
B6: Illustrative 12-month liquidity outlook based on operating cash flow trends. | L6: The table updates automatically based on the selected scenario in the Model Driver switch.
B8: Model Driver | C8: 3 | E8: Assumptions | G8: Value | H8: Notes
E9: Opening Cash (SEKm) | G9: =Inputs!H16 -> 1083 | H9: Cash at end of FY2024
E10: Revenue (SEKm) | G10: =Inputs!H7*(1+'Liquidity Forecast Simulation'!D13) -> 27850.64 | H10: Revenue + Revenue Growth
D12: Revenue Growth | E12: OCF Margin | F12: Capex (% of OCF) | G12: Debt Repayment (% of OCF) | H12: FX Impact (% of OCF) | I12: Working Capital Impact (% of OCF)
D13: {=INDEX(D15:D17,$C$8)} -> -0.03 | E13: {=INDEX(E15:E17,$C$8)} -> 0.085 | F13: {=INDEX(F15:F17,$C$8)} -> 0.04 | G13: {=INDEX(G15:G17,$C$8)} -> 0.3 | H13: {=INDEX(H15:H17,$C$8)} -> -0.05 | I13: {=INDEX(I15:I17,$C$8)} -> -0.03
B15: Base | D15: 0.02 | E15: 0.103 | F15: 0.06 | G15: 0.45 | H15: 0 | I15: 0
B16: Upside | D16: 0.05 | E16: 0.115 | F16: 0.08 | G16: 0.55 | H16: 0.02 | I16: 0.02
B17: Downside | D17: -0.03 | E17: 0.085 | F17: 0.04 | G17: 0.3 | H17: -0.05 | I17: -0.03
B20: Liquidity Forecast Table for 2025
B21: Month | C21: Opening Cash | D21: OCF | E21: Capex | F21: Debt Repayment | G21: FX Impact | H21: Working Capital Impact | I21: Closing Cash | J21: Liquidity Buffer
B23: Jan | C23: =G9 -> 1083 | D23: =$G$10*$E$13/12 -> 197.27537 | E23: =-D23*$F$13 -> -7.8910147 | F23: =$G$10*$E$13*$G$13/-12 -> -59.18261 | G23: =$G$10*$E$13*$H$13/12 -> -9.8637683 | H23: =$G$10*$E$13*$I$13/12 -> -5.918261 | I23: =SUM(C23:H23) -> 1197.4197 | J23: 800 | L23: ="Scenario Insight – "&IF(C8=1,"Base Case",IF(C8=2,"Upside Case","Downside Case")) -> Scenario Insight – Downside Case
B24: Feb | C24: =I23 -> 1197.4197 | D24: =$G$10*$E$13/12 -> 197.27537 | E24: =-D24*$F$13 -> -7.8910147 | F24: =$G$10*$E$13*$G$13/-12 -> -59.18261 | G24: =$G$10*$E$13*$H$13/12 -> -9.8637683 | H24: =$G$10*$E$13*$I$13/12 -> -5.918261 | I24: =SUM(C24:H24) -> 1311.8394 | J24: 800 | L24: {=_xlfn.IFS( C8=1,"Operating cash flow supports stable liquidity while debt continues to decline.", C8=2,"Stronger revenue growth and operating margins support accelerated liquidity accumulation.", C8=3,"Liquidity growth slows due to weaker operating cash flow and FX pressure, but the company remains capable of maintaining a positive cash position." )} -> Liquidity growth slows due to weaker operating cash flow and FX pressure, but the company remains capable of maintaining a positive cash position.
B25: Mar | C25: =I24 -> 1311.8394 | D25: =$G$10*$E$13/12 -> 197.27537 | E25: =-D25*$F$13 -> -7.8910147 | F25: =$G$10*$E$13*$G$13/-12 -> -59.18261 | G25: =$G$10*$E$13*$H$13/12 -> -9.8637683 | H25: =$G$10*$E$13*$I$13/12 -> -5.918261 | I25: =SUM(C25:H25) -> 1426.2591 | J25: 800
B26: Apr | C26: =I25 -> 1426.2591 | D26: =$G$10*$E$13/12 -> 197.27537 | E26: =-D26*$F$13 -> -7.8910147 | F26: =$G$10*$E$13*$G$13/-12 -> -59.18261 | G26: =$G$10*$E$13*$H$13/12 -> -9.8637683 | H26: =$G$10*$E$13*$I$13/12 -> -5.918261 | I26: =SUM(C26:H26) -> 1540.6789 | J26: 800
B27: May | C27: =I26 -> 1540.6789 | D27: =$G$10*$E$13/12 -> 197.27537 | E27: =-D27*$F$13 -> -7.8910147 | F27: =$G$10*$E$13*$G$13/-12 -> -59.18261 | G27: =$G$10*$E$13*$H$13/12 -> -9.8637683 | H27: =$G$10*$E$13*$I$13/12 -> -5.918261 | I27: =SUM(C27:H27) -> 1655.0986 | J27: 800
B28: Jun | C28: =I27 -> 1655.0986 | D28: =$G$10*$E$13/12 -> 197.27537 | E28: =-D28*$F$13 -> -7.8910147 | F28: =$G$10*$E$13*$G$13/-12 -> -59.18261 | G28: =$G$10*$E$13*$H$13/12 -> -9.8637683 | H28: =$G$10*$E$13*$I$13/12 -> -5.918261 | I28: =SUM(C28:H28) -> 1769.5183 | J28: 800
B29: Jul | C29: =I28 -> 1769.5183 | D29: =$G$10*$E$13/12 -> 197.27537 | E29: =-D29*$F$13 -> -7.8910147 | F29: =$G$10*$E$13*$G$13/-12 -> -59.18261 | G29: =$G$10*$E$13*$H$13/12 -> -9.8637683 | H29: =$G$10*$E$13*$I$13/12 -> -5.918261 | I29: =SUM(C29:H29) -> 1883.938 | J29: 800
B30: Aug | C30: =I29 -> 1883.938 | D30: =$G$10*$E$13/12 -> 197.27537 | E30: =-D30*$F$13 -> -7.8910147 | F30: =$G$10*$E$13*$G$13/-12 -> -59.18261 | G30: =$G$10*$E$13*$H$13/12 -> -9.8637683 | H30: =$G$10*$E$13*$I$13/12 -> -5.918261 | I30: =SUM(C30:H30) -> 1998.3577 | J30: 800
B31: Sep | C31: =I30 -> 1998.3577 | D31: =$G$10*$E$13/12 -> 197.27537 | E31: =-D31*$F$13 -> -7.8910147 | F31: =$G$10*$E$13*$G$13/-12 -> -59.18261 | G31: =$G$10*$E$13*$H$13/12 -> -9.8637683 | H31: =$G$10*$E$13*$I$13/12 -> -5.918261 | I31: =SUM(C31:H31) -> 2112.7774 | J31: 800
B32: Oct | C32: =I31 -> 2112.7774 | D32: =$G$10*$E$13/12 -> 197.27537 | E32: =-D32*$F$13 -> -7.8910147 | F32: =$G$10*$E$13*$G$13/-12 -> -59.18261 | G32: =$G$10*$E$13*$H$13/12 -> -9.8637683 | H32: =$G$10*$E$13*$I$13/12 -> -5.918261 | I32: =SUM(C32:H32) -> 2227.1971 | J32: 800
B33: Nov | C33: =I32 -> 2227.1971 | D33: =$G$10*$E$13/12 -> 197.27537 | E33: =-D33*$F$13 -> -7.8910147 | F33: =$G$10*$E$13*$G$13/-12 -> -59.18261 | G33: =$G$10*$E$13*$H$13/12 -> -9.8637683 | H33: =$G$10*$E$13*$I$13/12 -> -5.918261 | I33: =SUM(C33:H33) -> 2341.6168 | J33: 800
B34: Dec | C34: =I33 -> 2341.6168 | D34: =$G$10*$E$13/12 -> 197.27537 | E34: =-D34*$F$13 -> -7.8910147 | F34: =$G$10*$E$13*$G$13/-12 -> -59.18261 | G34: =$G$10*$E$13*$H$13/12 -> -9.8637683 | H34: =$G$10*$E$13*$I$13/12 -> -5.918261 | I34: =SUM(C34:H34) -> 2456.0366 | J34: 800
B37: Key Liquidity Insight
B38: Based on current operating cash flow levels, Sinch appears capable of maintaining a stable liquidity position while continuing to reduce debt.
B39: Scenario analysis highlights that liquidity remains resilient even under a downside case driven by weaker operating cash flow and FX pressure.
