Workbook

Sheet Cover
C11: Strategic Financial Analysis
C12: Can Volvo Reach 8% EBIT Margin by 2026?
C15: Table of Contents | K15: Strategic Goal
D17: Dashboard | K17: EBIT 2026 > 8% | L17: =IF(Model!C127>0.08,1,2) -> 1
D18: Model
D19: Financial Data
D20: Model Query
C28: Prepared as part of application for Finance Business Office & Strategy
C30: Felicia Nata, CTP
C31: Strategic Finance & Treasury Professional | Turning Financial Insight into Executive Decision Support
C36: This brief snapshot is based solely on publicly available information and is intended for discussion purposes only. The objective is to demonstrate analytical approach and driver-based thinking rather than provide a complete financial assessment.

Sheet Dashboard
B3: VOLVO Profitability Dashboard | P3: Scenario
B4: Can Volvo Reach 8% EBIT Margin by 2026?
B7: Revenue (2025) | G7: EBIT Margin (2025) | M7: R&D Intensity
B8: =Model!J11 -> 357263 | G8: =Model!J13 -> 0.001 | M8: =Model!J28 -> 0.072963055
B11: =Model!J43 -> -0.10736469 | G11: =Model!J14 -> -0.055 | M11: of Revenue
K26: EBIT Margin Sensitivity (2026)
L27: Research and Development
H28: Volume | L28: =Model!G114 -> 0.07 | M28: =Model!H114 -> 0.06 | N28: =Model!I114 -> 0.05 | O28: =Model!J114 -> 0.04 | P28: =Model!K114 -> 0.03
H29: =Model!J41 -> -0.069881803 | J29: Gross Margin | K29: =Model!F115 -> 0.18 | L29: =Model!G115 -> 0.018 | M29: =Model!H115 -> 0.028 | N29: =Model!I115 -> 0.038 | O29: =Model!J115 -> 0.048 | P29: =Model!K115 -> 0.058
H30: Revenue | K30: =Model!F116 -> 0.19 | L30: =Model!G116 -> 0.028 | M30: =Model!H116 -> 0.038 | N30: =Model!I116 -> 0.048 | O30: =Model!J116 -> 0.058 | P30: =Model!K116 -> 0.068
H31: =Model!J43 -> -0.10736469 | K31: =Model!F117 -> 0.2 | L31: =Model!G117 -> 0.038 | M31: =Model!H117 -> 0.048 | N31: =Model!I117 -> 0.058 | O31: =Model!J117 -> 0.068 | P31: =Model!K117 -> 0.078
K32: =Model!F118 -> 0.21 | L32: =Model!G118 -> 0.048 | M32: =Model!H118 -> 0.058 | N32: =Model!I118 -> 0.068 | O32: =Model!J118 -> 0.078 | P32: =Model!K118 -> 0.088
K33: =Model!F119 -> 0.22 | L33: =Model!G119 -> 0.058 | M33: =Model!H119 -> 0.068 | N33: =Model!I119 -> 0.078 | O33: =Model!J119 -> 0.088 | P33: =Model!K119 -> 0.098
B36: Key Insights
B37: 🟩 Profitability collapsed in 2025 due to rising R&D
B38: 🟩 8% target achievable only in upside scenario | G38: Disclaimer: This analysis is based solely on publicly available information and is intended to demonstrate analytical approach and driver-based financial modeling rather than provide a full valuation.
B39: 🟩 Gross margin recovery is the biggest driver
B40: 🟩 R&D must decline toward -8% to restore margins

Sheet Model
K1: Can Volvo Reach 8% EBIT Margin by 2026?
B3: Trend Analysis
B5: KEY FINDING Volvo’s profitability deteriorated significantly in 2025 as gross margins declined and R&D investment surged during the EV transition. Sensitivity analysis suggests that reaching the 8% EBIT margin target in 2026 requires a meaningful recovery in gross margins combined with a normalization of R&D spending.
B8: REVENUE AND MARGIN TREND
B10: All figures in SEK million unless stated | F10: 2021 | G10: 2022 | H10: 2023 | I10: 2024 | J10: 2025
B11: Revenue | F11: ='Financial Data'!D127 -> 282045 | G11: ='Financial Data'!E127 -> 330145 | H11: ='Financial Data'!F127 -> 399343 | I11: ='Financial Data'!G127 -> 400234 | J11: ='Financial Data'!H127 -> 357263
B12: Gross Margin (%) | F12: ='Financial Data'!D138/100 -> 0.216 | G12: ='Financial Data'!E138/100 -> 0.183 | H12: ='Financial Data'!F138/100 -> 0.194 | I12: ='Financial Data'!G138/100 -> 0.198 | J12: ='Financial Data'!H138/100 -> 0.169
B13: EBIT Margin (%) | F13: ='Financial Data'!D139/100 -> 0.072 | G13: ='Financial Data'!E139/100 -> 0.068 | H13: ='Financial Data'!F139/100 -> 0.05 | I13: ='Financial Data'!G139/100 -> 0.056 | J13: ='Financial Data'!H139/100 -> 0.001
B14: Change EBIT Margin (%) | G14: =G13-F13 -> -0.004 | H14: =H13-G13 -> -0.018 | I14: =I13-H13 -> 0.006 | J14: =J13-I13 -> -0.055
B16: Volvo had very strong growth from 2021–2023, then:
B17: • growth stalled in 2024
B18: • revenue declined sharply in 2025
B19: So the issue is recent, not structural across the entire period.
B20: Volvo’s profitability had already been gradually declining before the sharp 2025 collapse.
B21: Volvo has not reached 8% EBIT margin in the last five years.
B24: RESEARCH AND DEVELOPMENT INTENSITY
B26: All figures in SEK million unless stated | F26: 2021 | G26: 2022 | H26: 2023 | I26: 2024 | J26: 2025
B27: Research and Development | F27: ='Financial Data'!D128 -> -12714 | G27: ='Financial Data'!E128 -> -11514 | H27: ='Financial Data'!F128 -> -12884 | I27: ='Financial Data'!G128 -> -16983 | J27: ='Financial Data'!H128 -> -26067
B28: % of Revenue | F28: =-F27/F11 -> 0.045077913 | G28: =-G27/G11 -> 0.034875585 | H28: =-H27/H11 -> 0.032262992 | I28: =-I27/I11 -> 0.042432677 | J28: =-J27/J11 -> 0.072963055
B30: R&D spending more than doubled relative to revenue.
B31: This aligns with:
B32: • EV platform investment
B33: • battery technology
B34: • software development
B35: The EV transition has significantly increased Volvo’s development costs.
B37: VOLUME VS REVENUE
B39: All figures in SEK million unless stated | F39: 2021 | G39: 2022 | H39: 2023 | I39: 2024 | J39: 2025
B40: Unit Solds | F40: ='Financial Data'!D126 -> 698693 | G40: ='Financial Data'!E126 -> 615121 | H40: ='Financial Data'!F126 -> 708716 | I40: ='Financial Data'!G126 -> 763389 | J40: ='Financial Data'!H126 -> 710042
B41: Unit Solds (% Change) | G41: =G40/F40-1 -> -0.1196119 | H41: =H40/G40-1 -> 0.15215706 | I41: =I40/H40-1 -> 0.077143736 | J41: =J40/I40-1 -> -0.069881803
B42: Revenue | F42: =F11 -> 282045 | G42: =G11 -> 330145 | H42: =H11 -> 399343 | I42: =I11 -> 400234 | J42: =J11 -> 357263
B43: Revenue (% Change) | G43: =G42/F42-1 -> 0.17054016 | H43: =H42/G42-1 -> 0.20959881 | I43: =I42/H42-1 -> 0.0022311647 | J43: =J42/I42-1 -> -0.10736469
B45: Volumes dropped 7% in 2025, but revenue dropped 11%.
B46: Meaning:
B47: • pricing pressure
B48: • weaker product mix
B49: • discounting
B51: CASH FLOW TREND
B53: All figures in SEK million unless stated | F53: 2021 | G53: 2022 | H53: 2023 | I53: 2024 | J53: 2025
B54: Operating Cash Flow | F54: ='Financial Data'!D135 -> 29852 | G54: ='Financial Data'!E135 -> 33599 | H54: ='Financial Data'!F135 -> 42867 | I54: ='Financial Data'!G135 -> 47372 | J54: ='Financial Data'!H135 -> 34625
B56: Cash flow grew strongly until 2024 but declined in 2025.
...

Sheet Financial Data
H1: Can Volvo Reach 8% EBIT Margin by 2026?
B3: Income Statement
B5: All figures in SEK million unless stated | G5: Y2024 | H5: Y2025
B7: Revenue | G7: ='Model Query'!C180/1000000 -> 400234 | H7: ='Model Query'!D181/1000000 -> 357263
B8: Cost of Sales | G8: =-'Model Query'!C182/1000000 -> -320821 | H8: =-'Model Query'!D183/1000000 -> -297042
C9: Gross Income | G9: ='Model Query'!C184/1000000 -> 79413 | H9: ='Model Query'!D185/1000000 -> 60221
B11: Research And Development Expense | G11: =-'Model Query'!C186/1000000 -> -16983 | H11: =-'Model Query'!D187/1000000 -> -26067
B12: Selling Expense | G12: =-'Model Query'!C189/1000000 -> -25409 | H12: =-'Model Query'!D188/1000000 -> -23213
B13: Administrative Expense | G13: =-'Model Query'!C191/1000000 -> -12038 | H13: =-'Model Query'!D190/1000000 -> -10476
B14: Other Operating Income and Expense | G14: =('Model Query'!C193)/1000000 -> 2057 | H14: =('Model Query'!D192)/1000000 -> -816
B15: Share of Income in joint ventures and associates | G15: ='Model Query'!C195/1000000 -> -4722 | H15: ='Model Query'!D194/1000000 -> 654
C16: Operating Income | G16: ='Model Query'!C197/1000000 -> 22318 | H16: ='Model Query'!D196/1000000 -> 303
B18: Interest Income and Similar Credits | G18: ='Model Query'!C199/1000000 -> 2190 | H18: ='Model Query'!D198/1000000 -> 1929
B19: Interest Expense and Similar Changes | G19: =-'Model Query'!C201/1000000 -> -1164 | H19: =-'Model Query'!D200/1000000 -> -1251
B20: Other Financial Uncome and expenses | G20: ='Model Query'!C203/1000000 -> -625 | H20: ='Model Query'!D202/1000000 -> -1647
C21: Income Before Tax | G21: ='Model Query'!C205/1000000 -> 22719 | H21: ='Model Query'!D204/1000000 -> -666
B23: Income Tax | G23: =-'Model Query'!C207/1000000 -> -6785 | H23: =-'Model Query'!D206/1000000 -> -2302
C24: Net Income | G24: ='Model Query'!C208/1000000 -> 15934 | H24: ='Model Query'!D209/1000000 -> -2968
B26: Profit Loss Attributable To Owners Of Parent | G26: ='Model Query'!C210/1000000 -> 15401 | H26: ='Model Query'!D211/1000000 -> 174
B27: Profit Loss Attributable To Noncontrolling Interests | G27: ='Model Query'!C212/1000000 -> 533 | H27: ='Model Query'!D213/1000000 -> -3142
B30: Balance Sheet
B32: All figures in SEK million unless stated | G32: Y2024 | H32: Y2025
B34: ASSETS
B36: Non-Current Assets
B37: Intangible Assets And Goodwill | G37: ='Model Query'!C91/1000000 -> 83781 | H37: ='Model Query'!D92/1000000 -> 82965
B38: Property Plant And Equipment | G38: ='Model Query'!C93/1000000 -> 107124 | H38: ='Model Query'!D94/1000000 -> 99391
B39: Investment in Associates | G39: ='Model Query'!C95/1000000 -> 8998 | H39: ='Model Query'!D96/1000000 -> 7003
B40: Other Non-current Assets | G40: =('Model Query'!C97+'Model Query'!C100+'Model Query'!C102+'Model Query'!C104+'Model Query'!C106)/1000000 -> 29720 | H40: =('Model Query'!D98+'Model Query'!D99+'Model Query'!D101+'Model Query'!D103+'Model Query'!D105)/1000000 -> 26012
C41: Total Noncurrent Assets | G41: ='Model Query'!C108/1000000 -> 229623 | H41: ='Model Query'!D107/1000000 -> 215371
B43: Current Assets
B44: Inventories | G44: ='Model Query'!C110/1000000 -> 62455 | H44: ='Model Query'!D109/1000000 -> 59024
B45: Trade Receivables | G45: ='Model Query'!C111/1000000 -> 22780 | H45: ='Model Query'!D112/1000000 -> 21241
B46: Other Current Assets | G46: =('Model Query'!C113+'Model Query'!C115+'Model Query'!C117+'Model Query'!C119)/1000000 -> 17004 | H46: =('Model Query'!D114+'Model Query'!D116+'Model Query'!D118+'Model Query'!D120)/1000000 -> 19972
B47: Cash And Cash Equivalents | G47: ='Model Query'!C121/1000000 -> 56373 | H47: ='Model Query'!D122/1000000 -> 57564
C48: Total Current Assets | G48: ='Model Query'!C124/1000000 -> 158612 | H48: ='Model Query'!D123/1000000 -> 157801
B50: TOTAL ASSETS | G50: ='Model Query'!C126/1000000 -> 388235 | H50: ='Model Query'!D125/1000000 -> 373172
B52: EQUITY AND LIABILITIES
B54: EQUITY
B55: Equity Attributable To Owners Of Parent | G55: ='Model Query'!C128/1000000 -> 137461 | H55: ='Model Query'!D127/1000000 -> 147079
B56: Noncontrolling Interests | G56: ='Model Query'!C129/1000000 -> 4738 | H56: ='Model Query'!D130/1000000 -> 1299
...

Sheet Model Query
E1: Can Volvo Reach 8% EBIT Margin by 2026?
B3: Query - Cash Flow
B5: Account | C5: 2023 | D5: 2024 | E5: 2025
B6: Profit Loss From Operating Activities | D6: 22318000000
B7: Profit Loss From Operating Activities | E7: 303000000
B8: Adjustments For Depreciation And Amortisation Expense | D8: 22730000000
B9: Adjustments For Depreciation And Amortisation Expense | E9: 23945000000
B10: Dividends Received Classified As Operating Activities | D10: 213000000
B11: Dividends Received Classified As Operating Activities | E11: 205000000
B12: Interest Received Classified As Operating Activities | D12: 2190000000
B13: Interest Received Classified As Operating Activities | E13: 1929000000
B14: Interest Paid Classified As Operating Activities | E14: 1538000000
B15: Interest Paid Classified As Operating Activities | D15: 1623000000
B16: Finance Costs Paid And Finance Income Received Classified As Operating Activities | E16: 1963000000
B17: Finance Costs Paid And Finance Income Received Classified As Operating Activities | D17: 836000000
B18: Income Taxes Paid Classified As Operating Activities | E18: 3724000000
B19: Income Taxes Paid Classified As Operating Activities | D19: 4448000000
B20: Other Adjustments For Noncash Items | E20: 6281000000
B21: Other Adjustments For Noncash Items | D21: 2754000000
B22: Cash Flows From Used In Operations Before Changes In Working Capital | E22: 25438000000
B23: Cash Flows From Used In Operations Before Changes In Working Capital | D23: 43298000000
B24: Adjustments For Decrease Increase In Inventories | E24: 2353000000
B25: Adjustments For Decrease Increase In Inventories | D25: -2757000000
B26: Adjustments For Decrease Increase In Trade Account Receivable | D26: -1386000000
B27: Adjustments For Decrease Increase In Trade Account Receivable | E27: -84000000
B28: Adjustments For Increase Decrease In Trade Account Payable | D28: -7539000000
B29: Adjustments For Increase Decrease In Trade Account Payable | E29: 7205000000
B30: Adjustments For Provisions | D30: -1905000000
B31: Adjustments For Provisions | E31: -1867000000
B32: Adjustments For Increase Decrease In Contract Liabilities | D32: 8709000000
B33: Adjustments For Increase Decrease In Contract Liabilities | E33: 644000000
B34: Increase Decrease In Other Working Capital | D34: -8952000000
B35: Increase Decrease In Other Working Capital | E35: -936000000
B36: Increase Decrease In Working Capital | D36: -4074000000
B37: Increase Decrease In Working Capital | E37: -9187000000
B38: Cash Flows From Used In Operating Activities | D38: 47372000000
B39: Cash Flows From Used In Operating Activities | E39: 34625000000
B40: Investments In Shares And Participations Classified As Investing Activities | E40: -280000000
B41: Investments In Shares And Participations Classified As Investing Activities | D41: 1901000000
B42: Divestments In Shares And Participations Classified As Investing Activities | E42: 7716000000
...
